[2024-08-26T08:50:04.395-0500] {local_task_job_runner.py:123} INFO - ::group::Pre task execution logs
[2024-08-26T08:50:04.404-0500] {taskinstance.py:2603} INFO - Dependencies all met for dep_context=non-requeueable deps ti=<TaskInstance: mysql_to_postgresql_etl.load scheduled__2024-08-25T00:00:00+00:00 [queued]>
[2024-08-26T08:50:04.408-0500] {taskinstance.py:2603} INFO - Dependencies all met for dep_context=requeueable deps ti=<TaskInstance: mysql_to_postgresql_etl.load scheduled__2024-08-25T00:00:00+00:00 [queued]>
[2024-08-26T08:50:04.409-0500] {taskinstance.py:2856} INFO - Starting attempt 2 of 2
[2024-08-26T08:50:04.418-0500] {taskinstance.py:2879} INFO - Executing <Task(PythonOperator): load> on 2024-08-25 00:00:00+00:00
[2024-08-26T08:50:04.424-0500] {standard_task_runner.py:72} INFO - Started process 5672 to run task
[2024-08-26T08:50:04.430-0500] {standard_task_runner.py:104} INFO - Running: ['airflow', 'tasks', 'run', 'mysql_to_postgresql_etl', 'load', 'scheduled__2024-08-25T00:00:00+00:00', '--job-id', '10', '--raw', '--subdir', 'DAGS_FOLDER/test.py', '--cfg-path', '/var/folders/hk/x06l6x4x2tj6xw06th2r87h40000gn/T/tmpnynhi8w6']
[2024-08-26T08:50:04.433-0500] {standard_task_runner.py:105} INFO - Job 10: Subtask load
[2024-08-26T08:50:04.472-0500] {task_command.py:467} INFO - Running <TaskInstance: mysql_to_postgresql_etl.load scheduled__2024-08-25T00:00:00+00:00 [running]> on host jessicas-mbp.home
[2024-08-26T08:50:04.522-0500] {taskinstance.py:3122} INFO - Exporting env vars: AIRFLOW_CTX_DAG_OWNER='airflow' AIRFLOW_CTX_DAG_ID='mysql_to_postgresql_etl' AIRFLOW_CTX_TASK_ID='load' AIRFLOW_CTX_EXECUTION_DATE='2024-08-25T00:00:00+00:00' AIRFLOW_CTX_TRY_NUMBER='2' AIRFLOW_CTX_DAG_RUN_ID='scheduled__2024-08-25T00:00:00+00:00'
[2024-08-26T08:50:04.523-0500] {taskinstance.py:731} INFO - ::endgroup::
[2024-08-26T08:50:04.551-0500] {logging_mixin.py:190} WARNING - /Users/jessicamarzin/Desktop/data_science/etl_mysql_postgsql/airflow/dags/test.py:67 FutureWarning: Passing literal json to 'read_json' is deprecated and will be removed in a future version. To read from a literal string, wrap it in a 'StringIO' object.
[2024-08-26T08:50:04.607-0500] {taskinstance.py:3301} ERROR - Task failed with exception
Traceback (most recent call last):
  File "/usr/local/lib/python3.11/site-packages/airflow/models/taskinstance.py", line 767, in _execute_task
    result = _execute_callable(context=context, **execute_callable_kwargs)
             ^^^^^^^^^^^^^^^^^^^^^^^^^^^^^^^^^^^^^^^^^^^^^^^^^^^^^^^^^^^^^
  File "/usr/local/lib/python3.11/site-packages/airflow/models/taskinstance.py", line 733, in _execute_callable
    return ExecutionCallableRunner(
           ^^^^^^^^^^^^^^^^^^^^^^^^
  File "/usr/local/lib/python3.11/site-packages/airflow/utils/operator_helpers.py", line 252, in run
    return self.func(*args, **kwargs)
           ^^^^^^^^^^^^^^^^^^^^^^^^^^
  File "/usr/local/lib/python3.11/site-packages/airflow/models/baseoperator.py", line 406, in wrapper
    return func(self, *args, **kwargs)
           ^^^^^^^^^^^^^^^^^^^^^^^^^^^
  File "/usr/local/lib/python3.11/site-packages/airflow/operators/python.py", line 238, in execute
    return_value = self.execute_callable()
                   ^^^^^^^^^^^^^^^^^^^^^^^
  File "/usr/local/lib/python3.11/site-packages/airflow/operators/python.py", line 256, in execute_callable
    return runner.run(*self.op_args, **self.op_kwargs)
           ^^^^^^^^^^^^^^^^^^^^^^^^^^^^^^^^^^^^^^^^^^^
  File "/usr/local/lib/python3.11/site-packages/airflow/utils/operator_helpers.py", line 252, in run
    return self.func(*args, **kwargs)
           ^^^^^^^^^^^^^^^^^^^^^^^^^^
  File "/Users/jessicamarzin/Desktop/data_science/etl_mysql_postgsql/airflow/dags/test.py", line 69, in load
    conn = psycopg2.connect(
           ^^^^^^^^^^^^^^^^^
  File "/usr/local/lib/python3.11/site-packages/psycopg2/__init__.py", line 122, in connect
    conn = _connect(dsn, connection_factory=connection_factory, **kwasync)
           ^^^^^^^^^^^^^^^^^^^^^^^^^^^^^^^^^^^^^^^^^^^^^^^^^^^^^^^^^^^^^^^
psycopg2.OperationalError: connection to server at "localhost" (::1), port 5432 failed: FATAL:  password authentication failed for user "your_postgres_user"

[2024-08-26T08:50:04.614-0500] {taskinstance.py:1225} INFO - Marking task as FAILED. dag_id=mysql_to_postgresql_etl, task_id=load, run_id=scheduled__2024-08-25T00:00:00+00:00, execution_date=20240825T000000, start_date=20240826T135004, end_date=20240826T135004
[2024-08-26T08:50:04.622-0500] {taskinstance.py:340} INFO - ::group::Post task execution logs
[2024-08-26T08:50:04.622-0500] {standard_task_runner.py:124} ERROR - Failed to execute job 10 for task load (connection to server at "localhost" (::1), port 5432 failed: FATAL:  password authentication failed for user "your_postgres_user"
; 5672)
Traceback (most recent call last):
  File "/usr/local/lib/python3.11/site-packages/airflow/task/task_runner/standard_task_runner.py", line 117, in _start_by_fork
    ret = args.func(args, dag=self.dag)
          ^^^^^^^^^^^^^^^^^^^^^^^^^^^^^
  File "/usr/local/lib/python3.11/site-packages/airflow/cli/cli_config.py", line 49, in command
    return func(*args, **kwargs)
           ^^^^^^^^^^^^^^^^^^^^^
  File "/usr/local/lib/python3.11/site-packages/airflow/utils/cli.py", line 115, in wrapper
    return f(*args, **kwargs)
           ^^^^^^^^^^^^^^^^^^
  File "/usr/local/lib/python3.11/site-packages/airflow/cli/commands/task_command.py", line 483, in task_run
    task_return_code = _run_task_by_selected_method(args, _dag, ti)
                       ^^^^^^^^^^^^^^^^^^^^^^^^^^^^^^^^^^^^^^^^^^^^
  File "/usr/local/lib/python3.11/site-packages/airflow/cli/commands/task_command.py", line 256, in _run_task_by_selected_method
    return _run_raw_task(args, ti)
           ^^^^^^^^^^^^^^^^^^^^^^^
  File "/usr/local/lib/python3.11/site-packages/airflow/cli/commands/task_command.py", line 341, in _run_raw_task
    return ti._run_raw_task(
           ^^^^^^^^^^^^^^^^^
  File "/usr/local/lib/python3.11/site-packages/airflow/utils/session.py", line 97, in wrapper
    return func(*args, session=session, **kwargs)
           ^^^^^^^^^^^^^^^^^^^^^^^^^^^^^^^^^^^^^^
  File "/usr/local/lib/python3.11/site-packages/airflow/models/taskinstance.py", line 2995, in _run_raw_task
    return _run_raw_task(
           ^^^^^^^^^^^^^^
  File "/usr/local/lib/python3.11/site-packages/airflow/models/taskinstance.py", line 273, in _run_raw_task
    TaskInstance._execute_task_with_callbacks(
  File "/usr/local/lib/python3.11/site-packages/airflow/models/taskinstance.py", line 3149, in _execute_task_with_callbacks
    result = self._execute_task(context, task_orig)
             ^^^^^^^^^^^^^^^^^^^^^^^^^^^^^^^^^^^^^^
  File "/usr/local/lib/python3.11/site-packages/airflow/models/taskinstance.py", line 3173, in _execute_task
    return _execute_task(self, context, task_orig)
           ^^^^^^^^^^^^^^^^^^^^^^^^^^^^^^^^^^^^^^^
  File "/usr/local/lib/python3.11/site-packages/airflow/models/taskinstance.py", line 767, in _execute_task
    result = _execute_callable(context=context, **execute_callable_kwargs)
             ^^^^^^^^^^^^^^^^^^^^^^^^^^^^^^^^^^^^^^^^^^^^^^^^^^^^^^^^^^^^^
  File "/usr/local/lib/python3.11/site-packages/airflow/models/taskinstance.py", line 733, in _execute_callable
    return ExecutionCallableRunner(
           ^^^^^^^^^^^^^^^^^^^^^^^^
  File "/usr/local/lib/python3.11/site-packages/airflow/utils/operator_helpers.py", line 252, in run
    return self.func(*args, **kwargs)
           ^^^^^^^^^^^^^^^^^^^^^^^^^^
  File "/usr/local/lib/python3.11/site-packages/airflow/models/baseoperator.py", line 406, in wrapper
    return func(self, *args, **kwargs)
           ^^^^^^^^^^^^^^^^^^^^^^^^^^^
  File "/usr/local/lib/python3.11/site-packages/airflow/operators/python.py", line 238, in execute
    return_value = self.execute_callable()
                   ^^^^^^^^^^^^^^^^^^^^^^^
  File "/usr/local/lib/python3.11/site-packages/airflow/operators/python.py", line 256, in execute_callable
    return runner.run(*self.op_args, **self.op_kwargs)
           ^^^^^^^^^^^^^^^^^^^^^^^^^^^^^^^^^^^^^^^^^^^
  File "/usr/local/lib/python3.11/site-packages/airflow/utils/operator_helpers.py", line 252, in run
    return self.func(*args, **kwargs)
           ^^^^^^^^^^^^^^^^^^^^^^^^^^
  File "/Users/jessicamarzin/Desktop/data_science/etl_mysql_postgsql/airflow/dags/test.py", line 69, in load
    conn = psycopg2.connect(
           ^^^^^^^^^^^^^^^^^
  File "/usr/local/lib/python3.11/site-packages/psycopg2/__init__.py", line 122, in connect
    conn = _connect(dsn, connection_factory=connection_factory, **kwasync)
           ^^^^^^^^^^^^^^^^^^^^^^^^^^^^^^^^^^^^^^^^^^^^^^^^^^^^^^^^^^^^^^^
psycopg2.OperationalError: connection to server at "localhost" (::1), port 5432 failed: FATAL:  password authentication failed for user "your_postgres_user"

[2024-08-26T08:50:04.657-0500] {local_task_job_runner.py:261} INFO - Task exited with return code 1
[2024-08-26T08:50:04.669-0500] {taskinstance.py:3891} INFO - 0 downstream tasks scheduled from follow-on schedule check
[2024-08-26T08:50:04.670-0500] {local_task_job_runner.py:240} INFO - ::endgroup::
[2024-08-26T14:25:59.820-0500] {local_task_job_runner.py:123} INFO - ::group::Pre task execution logs
[2024-08-26T14:25:59.834-0500] {taskinstance.py:2603} INFO - Dependencies all met for dep_context=non-requeueable deps ti=<TaskInstance: mysql_to_postgresql_etl.load scheduled__2024-08-25T00:00:00+00:00 [queued]>
[2024-08-26T14:25:59.840-0500] {taskinstance.py:2603} INFO - Dependencies all met for dep_context=requeueable deps ti=<TaskInstance: mysql_to_postgresql_etl.load scheduled__2024-08-25T00:00:00+00:00 [queued]>
[2024-08-26T14:25:59.840-0500] {taskinstance.py:2856} INFO - Starting attempt 2 of 2
[2024-08-26T14:25:59.854-0500] {taskinstance.py:2879} INFO - Executing <Task(PythonOperator): load> on 2024-08-25 00:00:00+00:00
[2024-08-26T14:25:59.859-0500] {standard_task_runner.py:72} INFO - Started process 26108 to run task
[2024-08-26T14:25:59.865-0500] {standard_task_runner.py:104} INFO - Running: ['airflow', 'tasks', 'run', 'mysql_to_postgresql_etl', 'load', 'scheduled__2024-08-25T00:00:00+00:00', '--job-id', '23', '--raw', '--subdir', 'DAGS_FOLDER/test.py', '--cfg-path', '/var/folders/hk/x06l6x4x2tj6xw06th2r87h40000gn/T/tmpjfrbiamw']
[2024-08-26T14:25:59.868-0500] {standard_task_runner.py:105} INFO - Job 23: Subtask load
[2024-08-26T14:25:59.909-0500] {task_command.py:467} INFO - Running <TaskInstance: mysql_to_postgresql_etl.load scheduled__2024-08-25T00:00:00+00:00 [running]> on host jessicas-mbp.home
[2024-08-26T14:25:59.966-0500] {taskinstance.py:3122} INFO - Exporting env vars: AIRFLOW_CTX_DAG_OWNER='airflow' AIRFLOW_CTX_DAG_ID='mysql_to_postgresql_etl' AIRFLOW_CTX_TASK_ID='load' AIRFLOW_CTX_EXECUTION_DATE='2024-08-25T00:00:00+00:00' AIRFLOW_CTX_TRY_NUMBER='2' AIRFLOW_CTX_DAG_RUN_ID='scheduled__2024-08-25T00:00:00+00:00'
[2024-08-26T14:25:59.967-0500] {taskinstance.py:731} INFO - ::endgroup::
[2024-08-26T14:25:59.992-0500] {base.py:84} INFO - Retrieving connection 'postgres'
[2024-08-26T14:25:59.997-0500] {taskinstance.py:3301} ERROR - Task failed with exception
Traceback (most recent call last):
  File "/Users/jessicamarzin/Desktop/data_science/test_etl/venv/lib/python3.9/site-packages/airflow/models/taskinstance.py", line 767, in _execute_task
    result = _execute_callable(context=context, **execute_callable_kwargs)
  File "/Users/jessicamarzin/Desktop/data_science/test_etl/venv/lib/python3.9/site-packages/airflow/models/taskinstance.py", line 733, in _execute_callable
    return ExecutionCallableRunner(
  File "/Users/jessicamarzin/Desktop/data_science/test_etl/venv/lib/python3.9/site-packages/airflow/utils/operator_helpers.py", line 252, in run
    return self.func(*args, **kwargs)
  File "/Users/jessicamarzin/Desktop/data_science/test_etl/venv/lib/python3.9/site-packages/airflow/models/baseoperator.py", line 406, in wrapper
    return func(self, *args, **kwargs)
  File "/Users/jessicamarzin/Desktop/data_science/test_etl/venv/lib/python3.9/site-packages/airflow/operators/python.py", line 238, in execute
    return_value = self.execute_callable()
  File "/Users/jessicamarzin/Desktop/data_science/test_etl/venv/lib/python3.9/site-packages/airflow/operators/python.py", line 256, in execute_callable
    return runner.run(*self.op_args, **self.op_kwargs)
  File "/Users/jessicamarzin/Desktop/data_science/test_etl/venv/lib/python3.9/site-packages/airflow/utils/operator_helpers.py", line 252, in run
    return self.func(*args, **kwargs)
  File "/Users/jessicamarzin/Desktop/data_science/etl_mysql_postgsql/airflow/dags/test.py", line 67, in load
    conn = pg_hook.get_conn()
  File "/Users/jessicamarzin/Desktop/data_science/test_etl/venv/lib/python3.9/site-packages/airflow/providers/postgres/hooks/postgres.py", line 176, in get_conn
    self.conn = psycopg2.connect(**conn_args)
  File "/Users/jessicamarzin/Desktop/data_science/test_etl/venv/lib/python3.9/site-packages/psycopg2/__init__.py", line 122, in connect
    conn = _connect(dsn, connection_factory=connection_factory, **kwasync)
psycopg2.OperationalError: could not translate host name "postgres" to address: nodename nor servname provided, or not known

[2024-08-26T14:26:00.041-0500] {taskinstance.py:1225} INFO - Marking task as FAILED. dag_id=mysql_to_postgresql_etl, task_id=load, run_id=scheduled__2024-08-25T00:00:00+00:00, execution_date=20240825T000000, start_date=20240826T192559, end_date=20240826T192600
[2024-08-26T14:26:00.054-0500] {taskinstance.py:340} INFO - ::group::Post task execution logs
[2024-08-26T14:26:00.054-0500] {standard_task_runner.py:124} ERROR - Failed to execute job 23 for task load (could not translate host name "postgres" to address: nodename nor servname provided, or not known
; 26108)
Traceback (most recent call last):
  File "/Users/jessicamarzin/Desktop/data_science/test_etl/venv/lib/python3.9/site-packages/airflow/task/task_runner/standard_task_runner.py", line 117, in _start_by_fork
    ret = args.func(args, dag=self.dag)
  File "/Users/jessicamarzin/Desktop/data_science/test_etl/venv/lib/python3.9/site-packages/airflow/cli/cli_config.py", line 49, in command
    return func(*args, **kwargs)
  File "/Users/jessicamarzin/Desktop/data_science/test_etl/venv/lib/python3.9/site-packages/airflow/utils/cli.py", line 115, in wrapper
    return f(*args, **kwargs)
  File "/Users/jessicamarzin/Desktop/data_science/test_etl/venv/lib/python3.9/site-packages/airflow/cli/commands/task_command.py", line 483, in task_run
    task_return_code = _run_task_by_selected_method(args, _dag, ti)
  File "/Users/jessicamarzin/Desktop/data_science/test_etl/venv/lib/python3.9/site-packages/airflow/cli/commands/task_command.py", line 256, in _run_task_by_selected_method
    return _run_raw_task(args, ti)
  File "/Users/jessicamarzin/Desktop/data_science/test_etl/venv/lib/python3.9/site-packages/airflow/cli/commands/task_command.py", line 341, in _run_raw_task
    return ti._run_raw_task(
  File "/Users/jessicamarzin/Desktop/data_science/test_etl/venv/lib/python3.9/site-packages/airflow/utils/session.py", line 97, in wrapper
    return func(*args, session=session, **kwargs)
  File "/Users/jessicamarzin/Desktop/data_science/test_etl/venv/lib/python3.9/site-packages/airflow/models/taskinstance.py", line 2995, in _run_raw_task
    return _run_raw_task(
  File "/Users/jessicamarzin/Desktop/data_science/test_etl/venv/lib/python3.9/site-packages/airflow/models/taskinstance.py", line 273, in _run_raw_task
    TaskInstance._execute_task_with_callbacks(
  File "/Users/jessicamarzin/Desktop/data_science/test_etl/venv/lib/python3.9/site-packages/airflow/models/taskinstance.py", line 3149, in _execute_task_with_callbacks
    result = self._execute_task(context, task_orig)
  File "/Users/jessicamarzin/Desktop/data_science/test_etl/venv/lib/python3.9/site-packages/airflow/models/taskinstance.py", line 3173, in _execute_task
    return _execute_task(self, context, task_orig)
  File "/Users/jessicamarzin/Desktop/data_science/test_etl/venv/lib/python3.9/site-packages/airflow/models/taskinstance.py", line 767, in _execute_task
    result = _execute_callable(context=context, **execute_callable_kwargs)
  File "/Users/jessicamarzin/Desktop/data_science/test_etl/venv/lib/python3.9/site-packages/airflow/models/taskinstance.py", line 733, in _execute_callable
    return ExecutionCallableRunner(
  File "/Users/jessicamarzin/Desktop/data_science/test_etl/venv/lib/python3.9/site-packages/airflow/utils/operator_helpers.py", line 252, in run
    return self.func(*args, **kwargs)
  File "/Users/jessicamarzin/Desktop/data_science/test_etl/venv/lib/python3.9/site-packages/airflow/models/baseoperator.py", line 406, in wrapper
    return func(self, *args, **kwargs)
  File "/Users/jessicamarzin/Desktop/data_science/test_etl/venv/lib/python3.9/site-packages/airflow/operators/python.py", line 238, in execute
    return_value = self.execute_callable()
  File "/Users/jessicamarzin/Desktop/data_science/test_etl/venv/lib/python3.9/site-packages/airflow/operators/python.py", line 256, in execute_callable
    return runner.run(*self.op_args, **self.op_kwargs)
  File "/Users/jessicamarzin/Desktop/data_science/test_etl/venv/lib/python3.9/site-packages/airflow/utils/operator_helpers.py", line 252, in run
    return self.func(*args, **kwargs)
  File "/Users/jessicamarzin/Desktop/data_science/etl_mysql_postgsql/airflow/dags/test.py", line 67, in load
    conn = pg_hook.get_conn()
  File "/Users/jessicamarzin/Desktop/data_science/test_etl/venv/lib/python3.9/site-packages/airflow/providers/postgres/hooks/postgres.py", line 176, in get_conn
    self.conn = psycopg2.connect(**conn_args)
  File "/Users/jessicamarzin/Desktop/data_science/test_etl/venv/lib/python3.9/site-packages/psycopg2/__init__.py", line 122, in connect
    conn = _connect(dsn, connection_factory=connection_factory, **kwasync)
psycopg2.OperationalError: could not translate host name "postgres" to address: nodename nor servname provided, or not known

[2024-08-26T14:26:00.090-0500] {local_task_job_runner.py:261} INFO - Task exited with return code 1
[2024-08-26T14:26:00.103-0500] {taskinstance.py:3891} INFO - 0 downstream tasks scheduled from follow-on schedule check
[2024-08-26T14:26:00.104-0500] {local_task_job_runner.py:240} INFO - ::endgroup::
[2024-08-26T15:10:11.838-0500] {local_task_job_runner.py:123} INFO - ::group::Pre task execution logs
[2024-08-26T15:10:11.850-0500] {taskinstance.py:2603} INFO - Dependencies all met for dep_context=non-requeueable deps ti=<TaskInstance: mysql_to_postgresql_etl.load scheduled__2024-08-25T00:00:00+00:00 [queued]>
[2024-08-26T15:10:11.855-0500] {taskinstance.py:2603} INFO - Dependencies all met for dep_context=requeueable deps ti=<TaskInstance: mysql_to_postgresql_etl.load scheduled__2024-08-25T00:00:00+00:00 [queued]>
[2024-08-26T15:10:11.855-0500] {taskinstance.py:2856} INFO - Starting attempt 2 of 2
[2024-08-26T15:10:11.863-0500] {taskinstance.py:2879} INFO - Executing <Task(PythonOperator): load> on 2024-08-25 00:00:00+00:00
[2024-08-26T15:10:11.869-0500] {standard_task_runner.py:72} INFO - Started process 29730 to run task
[2024-08-26T15:10:11.875-0500] {standard_task_runner.py:104} INFO - Running: ['airflow', 'tasks', 'run', 'mysql_to_postgresql_etl', 'load', 'scheduled__2024-08-25T00:00:00+00:00', '--job-id', '31', '--raw', '--subdir', 'DAGS_FOLDER/test.py', '--cfg-path', '/var/folders/hk/x06l6x4x2tj6xw06th2r87h40000gn/T/tmpd3mrea5u']
[2024-08-26T15:10:11.878-0500] {standard_task_runner.py:105} INFO - Job 31: Subtask load
[2024-08-26T15:10:11.917-0500] {task_command.py:467} INFO - Running <TaskInstance: mysql_to_postgresql_etl.load scheduled__2024-08-25T00:00:00+00:00 [running]> on host jessicas-mbp.home
[2024-08-26T15:10:11.965-0500] {taskinstance.py:3122} INFO - Exporting env vars: AIRFLOW_CTX_DAG_OWNER='airflow' AIRFLOW_CTX_DAG_ID='mysql_to_postgresql_etl' AIRFLOW_CTX_TASK_ID='load' AIRFLOW_CTX_EXECUTION_DATE='2024-08-25T00:00:00+00:00' AIRFLOW_CTX_TRY_NUMBER='2' AIRFLOW_CTX_DAG_RUN_ID='scheduled__2024-08-25T00:00:00+00:00'
[2024-08-26T15:10:11.967-0500] {taskinstance.py:731} INFO - ::endgroup::
[2024-08-26T15:10:12.020-0500] {base.py:84} INFO - Retrieving connection 'postgres'
[2024-08-26T15:10:12.087-0500] {logging_mixin.py:190} INFO - Error in load task: connection to server at "localhost" (::1), port 5432 failed: FATAL:  database "airflow" does not exist
[2024-08-26T15:10:12.088-0500] {taskinstance.py:3301} ERROR - Task failed with exception
Traceback (most recent call last):
  File "/usr/local/lib/python3.11/site-packages/airflow/models/taskinstance.py", line 767, in _execute_task
    result = _execute_callable(context=context, **execute_callable_kwargs)
             ^^^^^^^^^^^^^^^^^^^^^^^^^^^^^^^^^^^^^^^^^^^^^^^^^^^^^^^^^^^^^
  File "/usr/local/lib/python3.11/site-packages/airflow/models/taskinstance.py", line 733, in _execute_callable
    return ExecutionCallableRunner(
           ^^^^^^^^^^^^^^^^^^^^^^^^
  File "/usr/local/lib/python3.11/site-packages/airflow/utils/operator_helpers.py", line 252, in run
    return self.func(*args, **kwargs)
           ^^^^^^^^^^^^^^^^^^^^^^^^^^
  File "/usr/local/lib/python3.11/site-packages/airflow/models/baseoperator.py", line 406, in wrapper
    return func(self, *args, **kwargs)
           ^^^^^^^^^^^^^^^^^^^^^^^^^^^
  File "/usr/local/lib/python3.11/site-packages/airflow/operators/python.py", line 238, in execute
    return_value = self.execute_callable()
                   ^^^^^^^^^^^^^^^^^^^^^^^
  File "/usr/local/lib/python3.11/site-packages/airflow/operators/python.py", line 256, in execute_callable
    return runner.run(*self.op_args, **self.op_kwargs)
           ^^^^^^^^^^^^^^^^^^^^^^^^^^^^^^^^^^^^^^^^^^^
  File "/usr/local/lib/python3.11/site-packages/airflow/utils/operator_helpers.py", line 252, in run
    return self.func(*args, **kwargs)
           ^^^^^^^^^^^^^^^^^^^^^^^^^^
  File "/Users/jessicamarzin/Desktop/data_science/etl_mysql_postgsql/airflow/dags/test.py", line 228, in load
    conn = pg_hook.get_conn()
           ^^^^^^^^^^^^^^^^^^
  File "/usr/local/lib/python3.11/site-packages/airflow/providers/postgres/hooks/postgres.py", line 176, in get_conn
    self.conn = psycopg2.connect(**conn_args)
                ^^^^^^^^^^^^^^^^^^^^^^^^^^^^^
  File "/usr/local/lib/python3.11/site-packages/psycopg2/__init__.py", line 122, in connect
    conn = _connect(dsn, connection_factory=connection_factory, **kwasync)
           ^^^^^^^^^^^^^^^^^^^^^^^^^^^^^^^^^^^^^^^^^^^^^^^^^^^^^^^^^^^^^^^
psycopg2.OperationalError: connection to server at "localhost" (::1), port 5432 failed: FATAL:  database "airflow" does not exist

[2024-08-26T15:10:12.094-0500] {taskinstance.py:1225} INFO - Marking task as FAILED. dag_id=mysql_to_postgresql_etl, task_id=load, run_id=scheduled__2024-08-25T00:00:00+00:00, execution_date=20240825T000000, start_date=20240826T201011, end_date=20240826T201012
[2024-08-26T15:10:12.101-0500] {taskinstance.py:340} INFO - ::group::Post task execution logs
[2024-08-26T15:10:12.102-0500] {standard_task_runner.py:124} ERROR - Failed to execute job 31 for task load (connection to server at "localhost" (::1), port 5432 failed: FATAL:  database "airflow" does not exist
; 29730)
Traceback (most recent call last):
  File "/usr/local/lib/python3.11/site-packages/airflow/task/task_runner/standard_task_runner.py", line 117, in _start_by_fork
    ret = args.func(args, dag=self.dag)
          ^^^^^^^^^^^^^^^^^^^^^^^^^^^^^
  File "/usr/local/lib/python3.11/site-packages/airflow/cli/cli_config.py", line 49, in command
    return func(*args, **kwargs)
           ^^^^^^^^^^^^^^^^^^^^^
  File "/usr/local/lib/python3.11/site-packages/airflow/utils/cli.py", line 115, in wrapper
    return f(*args, **kwargs)
           ^^^^^^^^^^^^^^^^^^
  File "/usr/local/lib/python3.11/site-packages/airflow/cli/commands/task_command.py", line 483, in task_run
    task_return_code = _run_task_by_selected_method(args, _dag, ti)
                       ^^^^^^^^^^^^^^^^^^^^^^^^^^^^^^^^^^^^^^^^^^^^
  File "/usr/local/lib/python3.11/site-packages/airflow/cli/commands/task_command.py", line 256, in _run_task_by_selected_method
    return _run_raw_task(args, ti)
           ^^^^^^^^^^^^^^^^^^^^^^^
  File "/usr/local/lib/python3.11/site-packages/airflow/cli/commands/task_command.py", line 341, in _run_raw_task
    return ti._run_raw_task(
           ^^^^^^^^^^^^^^^^^
  File "/usr/local/lib/python3.11/site-packages/airflow/utils/session.py", line 97, in wrapper
    return func(*args, session=session, **kwargs)
           ^^^^^^^^^^^^^^^^^^^^^^^^^^^^^^^^^^^^^^
  File "/usr/local/lib/python3.11/site-packages/airflow/models/taskinstance.py", line 2995, in _run_raw_task
    return _run_raw_task(
           ^^^^^^^^^^^^^^
  File "/usr/local/lib/python3.11/site-packages/airflow/models/taskinstance.py", line 273, in _run_raw_task
    TaskInstance._execute_task_with_callbacks(
  File "/usr/local/lib/python3.11/site-packages/airflow/models/taskinstance.py", line 3149, in _execute_task_with_callbacks
    result = self._execute_task(context, task_orig)
             ^^^^^^^^^^^^^^^^^^^^^^^^^^^^^^^^^^^^^^
  File "/usr/local/lib/python3.11/site-packages/airflow/models/taskinstance.py", line 3173, in _execute_task
    return _execute_task(self, context, task_orig)
           ^^^^^^^^^^^^^^^^^^^^^^^^^^^^^^^^^^^^^^^
  File "/usr/local/lib/python3.11/site-packages/airflow/models/taskinstance.py", line 767, in _execute_task
    result = _execute_callable(context=context, **execute_callable_kwargs)
             ^^^^^^^^^^^^^^^^^^^^^^^^^^^^^^^^^^^^^^^^^^^^^^^^^^^^^^^^^^^^^
  File "/usr/local/lib/python3.11/site-packages/airflow/models/taskinstance.py", line 733, in _execute_callable
    return ExecutionCallableRunner(
           ^^^^^^^^^^^^^^^^^^^^^^^^
  File "/usr/local/lib/python3.11/site-packages/airflow/utils/operator_helpers.py", line 252, in run
    return self.func(*args, **kwargs)
           ^^^^^^^^^^^^^^^^^^^^^^^^^^
  File "/usr/local/lib/python3.11/site-packages/airflow/models/baseoperator.py", line 406, in wrapper
    return func(self, *args, **kwargs)
           ^^^^^^^^^^^^^^^^^^^^^^^^^^^
  File "/usr/local/lib/python3.11/site-packages/airflow/operators/python.py", line 238, in execute
    return_value = self.execute_callable()
                   ^^^^^^^^^^^^^^^^^^^^^^^
  File "/usr/local/lib/python3.11/site-packages/airflow/operators/python.py", line 256, in execute_callable
    return runner.run(*self.op_args, **self.op_kwargs)
           ^^^^^^^^^^^^^^^^^^^^^^^^^^^^^^^^^^^^^^^^^^^
  File "/usr/local/lib/python3.11/site-packages/airflow/utils/operator_helpers.py", line 252, in run
    return self.func(*args, **kwargs)
           ^^^^^^^^^^^^^^^^^^^^^^^^^^
  File "/Users/jessicamarzin/Desktop/data_science/etl_mysql_postgsql/airflow/dags/test.py", line 228, in load
    conn = pg_hook.get_conn()
           ^^^^^^^^^^^^^^^^^^
  File "/usr/local/lib/python3.11/site-packages/airflow/providers/postgres/hooks/postgres.py", line 176, in get_conn
    self.conn = psycopg2.connect(**conn_args)
                ^^^^^^^^^^^^^^^^^^^^^^^^^^^^^
  File "/usr/local/lib/python3.11/site-packages/psycopg2/__init__.py", line 122, in connect
    conn = _connect(dsn, connection_factory=connection_factory, **kwasync)
           ^^^^^^^^^^^^^^^^^^^^^^^^^^^^^^^^^^^^^^^^^^^^^^^^^^^^^^^^^^^^^^^
psycopg2.OperationalError: connection to server at "localhost" (::1), port 5432 failed: FATAL:  database "airflow" does not exist

[2024-08-26T15:10:12.149-0500] {local_task_job_runner.py:261} INFO - Task exited with return code 1
[2024-08-26T15:10:12.162-0500] {taskinstance.py:3891} INFO - 0 downstream tasks scheduled from follow-on schedule check
[2024-08-26T15:10:12.163-0500] {local_task_job_runner.py:240} INFO - ::endgroup::
