[2024-08-26T08:45:01.751-0500] {local_task_job_runner.py:123} INFO - ::group::Pre task execution logs
[2024-08-26T08:45:01.759-0500] {taskinstance.py:2603} INFO - Dependencies all met for dep_context=non-requeueable deps ti=<TaskInstance: mysql_to_postgresql_etl.load scheduled__2024-08-25T00:00:00+00:00 [queued]>
[2024-08-26T08:45:01.764-0500] {taskinstance.py:2603} INFO - Dependencies all met for dep_context=requeueable deps ti=<TaskInstance: mysql_to_postgresql_etl.load scheduled__2024-08-25T00:00:00+00:00 [queued]>
[2024-08-26T08:45:01.764-0500] {taskinstance.py:2856} INFO - Starting attempt 1 of 2
[2024-08-26T08:45:01.773-0500] {taskinstance.py:2879} INFO - Executing <Task(PythonOperator): load> on 2024-08-25 00:00:00+00:00
[2024-08-26T08:45:01.779-0500] {standard_task_runner.py:72} INFO - Started process 5234 to run task
[2024-08-26T08:45:01.785-0500] {standard_task_runner.py:104} INFO - Running: ['airflow', 'tasks', 'run', 'mysql_to_postgresql_etl', 'load', 'scheduled__2024-08-25T00:00:00+00:00', '--job-id', '8', '--raw', '--subdir', 'DAGS_FOLDER/test.py', '--cfg-path', '/var/folders/hk/x06l6x4x2tj6xw06th2r87h40000gn/T/tmp5fitcdyq']
[2024-08-26T08:45:01.789-0500] {standard_task_runner.py:105} INFO - Job 8: Subtask load
[2024-08-26T08:45:01.828-0500] {task_command.py:467} INFO - Running <TaskInstance: mysql_to_postgresql_etl.load scheduled__2024-08-25T00:00:00+00:00 [running]> on host jessicas-mbp.home
[2024-08-26T08:45:01.882-0500] {taskinstance.py:3122} INFO - Exporting env vars: AIRFLOW_CTX_DAG_OWNER='airflow' AIRFLOW_CTX_DAG_ID='mysql_to_postgresql_etl' AIRFLOW_CTX_TASK_ID='load' AIRFLOW_CTX_EXECUTION_DATE='2024-08-25T00:00:00+00:00' AIRFLOW_CTX_TRY_NUMBER='1' AIRFLOW_CTX_DAG_RUN_ID='scheduled__2024-08-25T00:00:00+00:00'
[2024-08-26T08:45:01.883-0500] {taskinstance.py:731} INFO - ::endgroup::
[2024-08-26T08:45:01.907-0500] {logging_mixin.py:190} WARNING - /Users/jessicamarzin/Desktop/data_science/etl_mysql_postgsql/airflow/dags/test.py:67 FutureWarning: Passing literal json to 'read_json' is deprecated and will be removed in a future version. To read from a literal string, wrap it in a 'StringIO' object.
[2024-08-26T08:45:01.962-0500] {taskinstance.py:3301} ERROR - Task failed with exception
Traceback (most recent call last):
  File "/usr/local/lib/python3.11/site-packages/airflow/models/taskinstance.py", line 767, in _execute_task
    result = _execute_callable(context=context, **execute_callable_kwargs)
             ^^^^^^^^^^^^^^^^^^^^^^^^^^^^^^^^^^^^^^^^^^^^^^^^^^^^^^^^^^^^^
  File "/usr/local/lib/python3.11/site-packages/airflow/models/taskinstance.py", line 733, in _execute_callable
    return ExecutionCallableRunner(
           ^^^^^^^^^^^^^^^^^^^^^^^^
  File "/usr/local/lib/python3.11/site-packages/airflow/utils/operator_helpers.py", line 252, in run
    return self.func(*args, **kwargs)
           ^^^^^^^^^^^^^^^^^^^^^^^^^^
  File "/usr/local/lib/python3.11/site-packages/airflow/models/baseoperator.py", line 406, in wrapper
    return func(self, *args, **kwargs)
           ^^^^^^^^^^^^^^^^^^^^^^^^^^^
  File "/usr/local/lib/python3.11/site-packages/airflow/operators/python.py", line 238, in execute
    return_value = self.execute_callable()
                   ^^^^^^^^^^^^^^^^^^^^^^^
  File "/usr/local/lib/python3.11/site-packages/airflow/operators/python.py", line 256, in execute_callable
    return runner.run(*self.op_args, **self.op_kwargs)
           ^^^^^^^^^^^^^^^^^^^^^^^^^^^^^^^^^^^^^^^^^^^
  File "/usr/local/lib/python3.11/site-packages/airflow/utils/operator_helpers.py", line 252, in run
    return self.func(*args, **kwargs)
           ^^^^^^^^^^^^^^^^^^^^^^^^^^
  File "/Users/jessicamarzin/Desktop/data_science/etl_mysql_postgsql/airflow/dags/test.py", line 69, in load
    conn = psycopg2.connect(
           ^^^^^^^^^^^^^^^^^
  File "/usr/local/lib/python3.11/site-packages/psycopg2/__init__.py", line 122, in connect
    conn = _connect(dsn, connection_factory=connection_factory, **kwasync)
           ^^^^^^^^^^^^^^^^^^^^^^^^^^^^^^^^^^^^^^^^^^^^^^^^^^^^^^^^^^^^^^^
psycopg2.OperationalError: connection to server at "localhost" (::1), port 5432 failed: FATAL:  password authentication failed for user "your_postgres_user"

[2024-08-26T08:45:01.973-0500] {taskinstance.py:1225} INFO - Marking task as UP_FOR_RETRY. dag_id=mysql_to_postgresql_etl, task_id=load, run_id=scheduled__2024-08-25T00:00:00+00:00, execution_date=20240825T000000, start_date=20240826T134501, end_date=20240826T134501
[2024-08-26T08:45:01.984-0500] {taskinstance.py:340} INFO - ::group::Post task execution logs
[2024-08-26T08:45:01.985-0500] {standard_task_runner.py:124} ERROR - Failed to execute job 8 for task load (connection to server at "localhost" (::1), port 5432 failed: FATAL:  password authentication failed for user "your_postgres_user"
; 5234)
Traceback (most recent call last):
  File "/usr/local/lib/python3.11/site-packages/airflow/task/task_runner/standard_task_runner.py", line 117, in _start_by_fork
    ret = args.func(args, dag=self.dag)
          ^^^^^^^^^^^^^^^^^^^^^^^^^^^^^
  File "/usr/local/lib/python3.11/site-packages/airflow/cli/cli_config.py", line 49, in command
    return func(*args, **kwargs)
           ^^^^^^^^^^^^^^^^^^^^^
  File "/usr/local/lib/python3.11/site-packages/airflow/utils/cli.py", line 115, in wrapper
    return f(*args, **kwargs)
           ^^^^^^^^^^^^^^^^^^
  File "/usr/local/lib/python3.11/site-packages/airflow/cli/commands/task_command.py", line 483, in task_run
    task_return_code = _run_task_by_selected_method(args, _dag, ti)
                       ^^^^^^^^^^^^^^^^^^^^^^^^^^^^^^^^^^^^^^^^^^^^
  File "/usr/local/lib/python3.11/site-packages/airflow/cli/commands/task_command.py", line 256, in _run_task_by_selected_method
    return _run_raw_task(args, ti)
           ^^^^^^^^^^^^^^^^^^^^^^^
  File "/usr/local/lib/python3.11/site-packages/airflow/cli/commands/task_command.py", line 341, in _run_raw_task
    return ti._run_raw_task(
           ^^^^^^^^^^^^^^^^^
  File "/usr/local/lib/python3.11/site-packages/airflow/utils/session.py", line 97, in wrapper
    return func(*args, session=session, **kwargs)
           ^^^^^^^^^^^^^^^^^^^^^^^^^^^^^^^^^^^^^^
  File "/usr/local/lib/python3.11/site-packages/airflow/models/taskinstance.py", line 2995, in _run_raw_task
    return _run_raw_task(
           ^^^^^^^^^^^^^^
  File "/usr/local/lib/python3.11/site-packages/airflow/models/taskinstance.py", line 273, in _run_raw_task
    TaskInstance._execute_task_with_callbacks(
  File "/usr/local/lib/python3.11/site-packages/airflow/models/taskinstance.py", line 3149, in _execute_task_with_callbacks
    result = self._execute_task(context, task_orig)
             ^^^^^^^^^^^^^^^^^^^^^^^^^^^^^^^^^^^^^^
  File "/usr/local/lib/python3.11/site-packages/airflow/models/taskinstance.py", line 3173, in _execute_task
    return _execute_task(self, context, task_orig)
           ^^^^^^^^^^^^^^^^^^^^^^^^^^^^^^^^^^^^^^^
  File "/usr/local/lib/python3.11/site-packages/airflow/models/taskinstance.py", line 767, in _execute_task
    result = _execute_callable(context=context, **execute_callable_kwargs)
             ^^^^^^^^^^^^^^^^^^^^^^^^^^^^^^^^^^^^^^^^^^^^^^^^^^^^^^^^^^^^^
  File "/usr/local/lib/python3.11/site-packages/airflow/models/taskinstance.py", line 733, in _execute_callable
    return ExecutionCallableRunner(
           ^^^^^^^^^^^^^^^^^^^^^^^^
  File "/usr/local/lib/python3.11/site-packages/airflow/utils/operator_helpers.py", line 252, in run
    return self.func(*args, **kwargs)
           ^^^^^^^^^^^^^^^^^^^^^^^^^^
  File "/usr/local/lib/python3.11/site-packages/airflow/models/baseoperator.py", line 406, in wrapper
    return func(self, *args, **kwargs)
           ^^^^^^^^^^^^^^^^^^^^^^^^^^^
  File "/usr/local/lib/python3.11/site-packages/airflow/operators/python.py", line 238, in execute
    return_value = self.execute_callable()
                   ^^^^^^^^^^^^^^^^^^^^^^^
  File "/usr/local/lib/python3.11/site-packages/airflow/operators/python.py", line 256, in execute_callable
    return runner.run(*self.op_args, **self.op_kwargs)
           ^^^^^^^^^^^^^^^^^^^^^^^^^^^^^^^^^^^^^^^^^^^
  File "/usr/local/lib/python3.11/site-packages/airflow/utils/operator_helpers.py", line 252, in run
    return self.func(*args, **kwargs)
           ^^^^^^^^^^^^^^^^^^^^^^^^^^
  File "/Users/jessicamarzin/Desktop/data_science/etl_mysql_postgsql/airflow/dags/test.py", line 69, in load
    conn = psycopg2.connect(
           ^^^^^^^^^^^^^^^^^
  File "/usr/local/lib/python3.11/site-packages/psycopg2/__init__.py", line 122, in connect
    conn = _connect(dsn, connection_factory=connection_factory, **kwasync)
           ^^^^^^^^^^^^^^^^^^^^^^^^^^^^^^^^^^^^^^^^^^^^^^^^^^^^^^^^^^^^^^^
psycopg2.OperationalError: connection to server at "localhost" (::1), port 5432 failed: FATAL:  password authentication failed for user "your_postgres_user"

[2024-08-26T08:45:02.018-0500] {local_task_job_runner.py:261} INFO - Task exited with return code 1
[2024-08-26T08:45:02.030-0500] {taskinstance.py:3891} INFO - 0 downstream tasks scheduled from follow-on schedule check
[2024-08-26T08:45:02.030-0500] {local_task_job_runner.py:240} INFO - ::endgroup::
[2024-08-26T14:20:56.493-0500] {local_task_job_runner.py:123} INFO - ::group::Pre task execution logs
[2024-08-26T14:20:56.504-0500] {taskinstance.py:2603} INFO - Dependencies all met for dep_context=non-requeueable deps ti=<TaskInstance: mysql_to_postgresql_etl.load scheduled__2024-08-25T00:00:00+00:00 [queued]>
[2024-08-26T14:20:56.510-0500] {taskinstance.py:2603} INFO - Dependencies all met for dep_context=requeueable deps ti=<TaskInstance: mysql_to_postgresql_etl.load scheduled__2024-08-25T00:00:00+00:00 [queued]>
[2024-08-26T14:20:56.510-0500] {taskinstance.py:2856} INFO - Starting attempt 1 of 2
[2024-08-26T14:20:56.521-0500] {taskinstance.py:2879} INFO - Executing <Task(PythonOperator): load> on 2024-08-25 00:00:00+00:00
[2024-08-26T14:20:56.526-0500] {standard_task_runner.py:72} INFO - Started process 25625 to run task
[2024-08-26T14:20:56.533-0500] {standard_task_runner.py:104} INFO - Running: ['airflow', 'tasks', 'run', 'mysql_to_postgresql_etl', 'load', 'scheduled__2024-08-25T00:00:00+00:00', '--job-id', '21', '--raw', '--subdir', 'DAGS_FOLDER/test.py', '--cfg-path', '/var/folders/hk/x06l6x4x2tj6xw06th2r87h40000gn/T/tmpt0kzwxy5']
[2024-08-26T14:20:56.536-0500] {standard_task_runner.py:105} INFO - Job 21: Subtask load
[2024-08-26T14:20:56.576-0500] {task_command.py:467} INFO - Running <TaskInstance: mysql_to_postgresql_etl.load scheduled__2024-08-25T00:00:00+00:00 [running]> on host jessicas-mbp.home
[2024-08-26T14:20:56.637-0500] {taskinstance.py:3122} INFO - Exporting env vars: AIRFLOW_CTX_DAG_OWNER='airflow' AIRFLOW_CTX_DAG_ID='mysql_to_postgresql_etl' AIRFLOW_CTX_TASK_ID='load' AIRFLOW_CTX_EXECUTION_DATE='2024-08-25T00:00:00+00:00' AIRFLOW_CTX_TRY_NUMBER='1' AIRFLOW_CTX_DAG_RUN_ID='scheduled__2024-08-25T00:00:00+00:00'
[2024-08-26T14:20:56.638-0500] {taskinstance.py:731} INFO - ::endgroup::
[2024-08-26T14:20:56.663-0500] {base.py:84} INFO - Retrieving connection 'postgres'
[2024-08-26T14:20:56.670-0500] {taskinstance.py:3301} ERROR - Task failed with exception
Traceback (most recent call last):
  File "/Users/jessicamarzin/Desktop/data_science/test_etl/venv/lib/python3.9/site-packages/airflow/models/taskinstance.py", line 767, in _execute_task
    result = _execute_callable(context=context, **execute_callable_kwargs)
  File "/Users/jessicamarzin/Desktop/data_science/test_etl/venv/lib/python3.9/site-packages/airflow/models/taskinstance.py", line 733, in _execute_callable
    return ExecutionCallableRunner(
  File "/Users/jessicamarzin/Desktop/data_science/test_etl/venv/lib/python3.9/site-packages/airflow/utils/operator_helpers.py", line 252, in run
    return self.func(*args, **kwargs)
  File "/Users/jessicamarzin/Desktop/data_science/test_etl/venv/lib/python3.9/site-packages/airflow/models/baseoperator.py", line 406, in wrapper
    return func(self, *args, **kwargs)
  File "/Users/jessicamarzin/Desktop/data_science/test_etl/venv/lib/python3.9/site-packages/airflow/operators/python.py", line 238, in execute
    return_value = self.execute_callable()
  File "/Users/jessicamarzin/Desktop/data_science/test_etl/venv/lib/python3.9/site-packages/airflow/operators/python.py", line 256, in execute_callable
    return runner.run(*self.op_args, **self.op_kwargs)
  File "/Users/jessicamarzin/Desktop/data_science/test_etl/venv/lib/python3.9/site-packages/airflow/utils/operator_helpers.py", line 252, in run
    return self.func(*args, **kwargs)
  File "/Users/jessicamarzin/Desktop/data_science/etl_mysql_postgsql/airflow/dags/test.py", line 67, in load
    conn = pg_hook.get_conn()
  File "/Users/jessicamarzin/Desktop/data_science/test_etl/venv/lib/python3.9/site-packages/airflow/providers/postgres/hooks/postgres.py", line 176, in get_conn
    self.conn = psycopg2.connect(**conn_args)
  File "/Users/jessicamarzin/Desktop/data_science/test_etl/venv/lib/python3.9/site-packages/psycopg2/__init__.py", line 122, in connect
    conn = _connect(dsn, connection_factory=connection_factory, **kwasync)
psycopg2.OperationalError: could not translate host name "postgres" to address: nodename nor servname provided, or not known

[2024-08-26T14:20:56.716-0500] {taskinstance.py:1225} INFO - Marking task as UP_FOR_RETRY. dag_id=mysql_to_postgresql_etl, task_id=load, run_id=scheduled__2024-08-25T00:00:00+00:00, execution_date=20240825T000000, start_date=20240826T192056, end_date=20240826T192056
[2024-08-26T14:20:56.727-0500] {taskinstance.py:340} INFO - ::group::Post task execution logs
[2024-08-26T14:20:56.727-0500] {standard_task_runner.py:124} ERROR - Failed to execute job 21 for task load (could not translate host name "postgres" to address: nodename nor servname provided, or not known
; 25625)
Traceback (most recent call last):
  File "/Users/jessicamarzin/Desktop/data_science/test_etl/venv/lib/python3.9/site-packages/airflow/task/task_runner/standard_task_runner.py", line 117, in _start_by_fork
    ret = args.func(args, dag=self.dag)
  File "/Users/jessicamarzin/Desktop/data_science/test_etl/venv/lib/python3.9/site-packages/airflow/cli/cli_config.py", line 49, in command
    return func(*args, **kwargs)
  File "/Users/jessicamarzin/Desktop/data_science/test_etl/venv/lib/python3.9/site-packages/airflow/utils/cli.py", line 115, in wrapper
    return f(*args, **kwargs)
  File "/Users/jessicamarzin/Desktop/data_science/test_etl/venv/lib/python3.9/site-packages/airflow/cli/commands/task_command.py", line 483, in task_run
    task_return_code = _run_task_by_selected_method(args, _dag, ti)
  File "/Users/jessicamarzin/Desktop/data_science/test_etl/venv/lib/python3.9/site-packages/airflow/cli/commands/task_command.py", line 256, in _run_task_by_selected_method
    return _run_raw_task(args, ti)
  File "/Users/jessicamarzin/Desktop/data_science/test_etl/venv/lib/python3.9/site-packages/airflow/cli/commands/task_command.py", line 341, in _run_raw_task
    return ti._run_raw_task(
  File "/Users/jessicamarzin/Desktop/data_science/test_etl/venv/lib/python3.9/site-packages/airflow/utils/session.py", line 97, in wrapper
    return func(*args, session=session, **kwargs)
  File "/Users/jessicamarzin/Desktop/data_science/test_etl/venv/lib/python3.9/site-packages/airflow/models/taskinstance.py", line 2995, in _run_raw_task
    return _run_raw_task(
  File "/Users/jessicamarzin/Desktop/data_science/test_etl/venv/lib/python3.9/site-packages/airflow/models/taskinstance.py", line 273, in _run_raw_task
    TaskInstance._execute_task_with_callbacks(
  File "/Users/jessicamarzin/Desktop/data_science/test_etl/venv/lib/python3.9/site-packages/airflow/models/taskinstance.py", line 3149, in _execute_task_with_callbacks
    result = self._execute_task(context, task_orig)
  File "/Users/jessicamarzin/Desktop/data_science/test_etl/venv/lib/python3.9/site-packages/airflow/models/taskinstance.py", line 3173, in _execute_task
    return _execute_task(self, context, task_orig)
  File "/Users/jessicamarzin/Desktop/data_science/test_etl/venv/lib/python3.9/site-packages/airflow/models/taskinstance.py", line 767, in _execute_task
    result = _execute_callable(context=context, **execute_callable_kwargs)
  File "/Users/jessicamarzin/Desktop/data_science/test_etl/venv/lib/python3.9/site-packages/airflow/models/taskinstance.py", line 733, in _execute_callable
    return ExecutionCallableRunner(
  File "/Users/jessicamarzin/Desktop/data_science/test_etl/venv/lib/python3.9/site-packages/airflow/utils/operator_helpers.py", line 252, in run
    return self.func(*args, **kwargs)
  File "/Users/jessicamarzin/Desktop/data_science/test_etl/venv/lib/python3.9/site-packages/airflow/models/baseoperator.py", line 406, in wrapper
    return func(self, *args, **kwargs)
  File "/Users/jessicamarzin/Desktop/data_science/test_etl/venv/lib/python3.9/site-packages/airflow/operators/python.py", line 238, in execute
    return_value = self.execute_callable()
  File "/Users/jessicamarzin/Desktop/data_science/test_etl/venv/lib/python3.9/site-packages/airflow/operators/python.py", line 256, in execute_callable
    return runner.run(*self.op_args, **self.op_kwargs)
  File "/Users/jessicamarzin/Desktop/data_science/test_etl/venv/lib/python3.9/site-packages/airflow/utils/operator_helpers.py", line 252, in run
    return self.func(*args, **kwargs)
  File "/Users/jessicamarzin/Desktop/data_science/etl_mysql_postgsql/airflow/dags/test.py", line 67, in load
    conn = pg_hook.get_conn()
  File "/Users/jessicamarzin/Desktop/data_science/test_etl/venv/lib/python3.9/site-packages/airflow/providers/postgres/hooks/postgres.py", line 176, in get_conn
    self.conn = psycopg2.connect(**conn_args)
  File "/Users/jessicamarzin/Desktop/data_science/test_etl/venv/lib/python3.9/site-packages/psycopg2/__init__.py", line 122, in connect
    conn = _connect(dsn, connection_factory=connection_factory, **kwasync)
psycopg2.OperationalError: could not translate host name "postgres" to address: nodename nor servname provided, or not known

[2024-08-26T14:20:56.763-0500] {local_task_job_runner.py:261} INFO - Task exited with return code 1
[2024-08-26T14:20:56.776-0500] {taskinstance.py:3891} INFO - 0 downstream tasks scheduled from follow-on schedule check
[2024-08-26T14:20:56.776-0500] {local_task_job_runner.py:240} INFO - ::endgroup::
[2024-08-26T14:28:54.272-0500] {local_task_job_runner.py:123} INFO - ::group::Pre task execution logs
[2024-08-26T14:28:54.293-0500] {taskinstance.py:2603} INFO - Dependencies all met for dep_context=non-requeueable deps ti=<TaskInstance: mysql_to_postgresql_etl.load scheduled__2024-08-25T00:00:00+00:00 [queued]>
[2024-08-26T14:28:54.302-0500] {taskinstance.py:2603} INFO - Dependencies all met for dep_context=requeueable deps ti=<TaskInstance: mysql_to_postgresql_etl.load scheduled__2024-08-25T00:00:00+00:00 [queued]>
[2024-08-26T14:28:54.302-0500] {taskinstance.py:2856} INFO - Starting attempt 1 of 2
[2024-08-26T14:28:54.321-0500] {taskinstance.py:2879} INFO - Executing <Task(PythonOperator): load> on 2024-08-25 00:00:00+00:00
[2024-08-26T14:28:54.330-0500] {standard_task_runner.py:72} INFO - Started process 26541 to run task
[2024-08-26T14:28:54.339-0500] {standard_task_runner.py:104} INFO - Running: ['airflow', 'tasks', 'run', 'mysql_to_postgresql_etl', 'load', 'scheduled__2024-08-25T00:00:00+00:00', '--job-id', '27', '--raw', '--subdir', 'DAGS_FOLDER/test.py', '--cfg-path', '/var/folders/hk/x06l6x4x2tj6xw06th2r87h40000gn/T/tmpan49rhma']
[2024-08-26T14:28:54.344-0500] {standard_task_runner.py:105} INFO - Job 27: Subtask load
[2024-08-26T14:28:54.407-0500] {task_command.py:467} INFO - Running <TaskInstance: mysql_to_postgresql_etl.load scheduled__2024-08-25T00:00:00+00:00 [running]> on host jessicas-mbp.home
[2024-08-26T14:28:54.495-0500] {taskinstance.py:3122} INFO - Exporting env vars: AIRFLOW_CTX_DAG_OWNER='airflow' AIRFLOW_CTX_DAG_ID='mysql_to_postgresql_etl' AIRFLOW_CTX_TASK_ID='load' AIRFLOW_CTX_EXECUTION_DATE='2024-08-25T00:00:00+00:00' AIRFLOW_CTX_TRY_NUMBER='1' AIRFLOW_CTX_DAG_RUN_ID='scheduled__2024-08-25T00:00:00+00:00'
[2024-08-26T14:28:54.497-0500] {taskinstance.py:731} INFO - ::endgroup::
[2024-08-26T14:28:54.529-0500] {base.py:84} INFO - Retrieving connection 'postgres'
[2024-08-26T14:28:54.578-0500] {taskinstance.py:3301} ERROR - Task failed with exception
Traceback (most recent call last):
  File "/Users/jessicamarzin/Desktop/data_science/test_etl/venv/lib/python3.9/site-packages/airflow/models/taskinstance.py", line 767, in _execute_task
    result = _execute_callable(context=context, **execute_callable_kwargs)
  File "/Users/jessicamarzin/Desktop/data_science/test_etl/venv/lib/python3.9/site-packages/airflow/models/taskinstance.py", line 733, in _execute_callable
    return ExecutionCallableRunner(
  File "/Users/jessicamarzin/Desktop/data_science/test_etl/venv/lib/python3.9/site-packages/airflow/utils/operator_helpers.py", line 252, in run
    return self.func(*args, **kwargs)
  File "/Users/jessicamarzin/Desktop/data_science/test_etl/venv/lib/python3.9/site-packages/airflow/models/baseoperator.py", line 406, in wrapper
    return func(self, *args, **kwargs)
  File "/Users/jessicamarzin/Desktop/data_science/test_etl/venv/lib/python3.9/site-packages/airflow/operators/python.py", line 238, in execute
    return_value = self.execute_callable()
  File "/Users/jessicamarzin/Desktop/data_science/test_etl/venv/lib/python3.9/site-packages/airflow/operators/python.py", line 256, in execute_callable
    return runner.run(*self.op_args, **self.op_kwargs)
  File "/Users/jessicamarzin/Desktop/data_science/test_etl/venv/lib/python3.9/site-packages/airflow/utils/operator_helpers.py", line 252, in run
    return self.func(*args, **kwargs)
  File "/Users/jessicamarzin/Desktop/data_science/etl_mysql_postgsql/airflow/dags/test.py", line 67, in load
    conn = pg_hook.get_conn()
  File "/Users/jessicamarzin/Desktop/data_science/test_etl/venv/lib/python3.9/site-packages/airflow/providers/postgres/hooks/postgres.py", line 176, in get_conn
    self.conn = psycopg2.connect(**conn_args)
  File "/Users/jessicamarzin/Desktop/data_science/test_etl/venv/lib/python3.9/site-packages/psycopg2/__init__.py", line 122, in connect
    conn = _connect(dsn, connection_factory=connection_factory, **kwasync)
psycopg2.OperationalError: connection to server at "localhost" (::1), port 5432 failed: FATAL:  database "airflow" does not exist

[2024-08-26T14:28:54.650-0500] {taskinstance.py:1225} INFO - Marking task as UP_FOR_RETRY. dag_id=mysql_to_postgresql_etl, task_id=load, run_id=scheduled__2024-08-25T00:00:00+00:00, execution_date=20240825T000000, start_date=20240826T192854, end_date=20240826T192854
[2024-08-26T14:28:54.670-0500] {taskinstance.py:340} INFO - ::group::Post task execution logs
[2024-08-26T14:28:54.671-0500] {standard_task_runner.py:124} ERROR - Failed to execute job 27 for task load (connection to server at "localhost" (::1), port 5432 failed: FATAL:  database "airflow" does not exist
; 26541)
Traceback (most recent call last):
  File "/Users/jessicamarzin/Desktop/data_science/test_etl/venv/lib/python3.9/site-packages/airflow/task/task_runner/standard_task_runner.py", line 117, in _start_by_fork
    ret = args.func(args, dag=self.dag)
  File "/Users/jessicamarzin/Desktop/data_science/test_etl/venv/lib/python3.9/site-packages/airflow/cli/cli_config.py", line 49, in command
    return func(*args, **kwargs)
  File "/Users/jessicamarzin/Desktop/data_science/test_etl/venv/lib/python3.9/site-packages/airflow/utils/cli.py", line 115, in wrapper
    return f(*args, **kwargs)
  File "/Users/jessicamarzin/Desktop/data_science/test_etl/venv/lib/python3.9/site-packages/airflow/cli/commands/task_command.py", line 483, in task_run
    task_return_code = _run_task_by_selected_method(args, _dag, ti)
  File "/Users/jessicamarzin/Desktop/data_science/test_etl/venv/lib/python3.9/site-packages/airflow/cli/commands/task_command.py", line 256, in _run_task_by_selected_method
    return _run_raw_task(args, ti)
  File "/Users/jessicamarzin/Desktop/data_science/test_etl/venv/lib/python3.9/site-packages/airflow/cli/commands/task_command.py", line 341, in _run_raw_task
    return ti._run_raw_task(
  File "/Users/jessicamarzin/Desktop/data_science/test_etl/venv/lib/python3.9/site-packages/airflow/utils/session.py", line 97, in wrapper
    return func(*args, session=session, **kwargs)
  File "/Users/jessicamarzin/Desktop/data_science/test_etl/venv/lib/python3.9/site-packages/airflow/models/taskinstance.py", line 2995, in _run_raw_task
    return _run_raw_task(
  File "/Users/jessicamarzin/Desktop/data_science/test_etl/venv/lib/python3.9/site-packages/airflow/models/taskinstance.py", line 273, in _run_raw_task
    TaskInstance._execute_task_with_callbacks(
  File "/Users/jessicamarzin/Desktop/data_science/test_etl/venv/lib/python3.9/site-packages/airflow/models/taskinstance.py", line 3149, in _execute_task_with_callbacks
    result = self._execute_task(context, task_orig)
  File "/Users/jessicamarzin/Desktop/data_science/test_etl/venv/lib/python3.9/site-packages/airflow/models/taskinstance.py", line 3173, in _execute_task
    return _execute_task(self, context, task_orig)
  File "/Users/jessicamarzin/Desktop/data_science/test_etl/venv/lib/python3.9/site-packages/airflow/models/taskinstance.py", line 767, in _execute_task
    result = _execute_callable(context=context, **execute_callable_kwargs)
  File "/Users/jessicamarzin/Desktop/data_science/test_etl/venv/lib/python3.9/site-packages/airflow/models/taskinstance.py", line 733, in _execute_callable
    return ExecutionCallableRunner(
  File "/Users/jessicamarzin/Desktop/data_science/test_etl/venv/lib/python3.9/site-packages/airflow/utils/operator_helpers.py", line 252, in run
    return self.func(*args, **kwargs)
  File "/Users/jessicamarzin/Desktop/data_science/test_etl/venv/lib/python3.9/site-packages/airflow/models/baseoperator.py", line 406, in wrapper
    return func(self, *args, **kwargs)
  File "/Users/jessicamarzin/Desktop/data_science/test_etl/venv/lib/python3.9/site-packages/airflow/operators/python.py", line 238, in execute
    return_value = self.execute_callable()
  File "/Users/jessicamarzin/Desktop/data_science/test_etl/venv/lib/python3.9/site-packages/airflow/operators/python.py", line 256, in execute_callable
    return runner.run(*self.op_args, **self.op_kwargs)
  File "/Users/jessicamarzin/Desktop/data_science/test_etl/venv/lib/python3.9/site-packages/airflow/utils/operator_helpers.py", line 252, in run
    return self.func(*args, **kwargs)
  File "/Users/jessicamarzin/Desktop/data_science/etl_mysql_postgsql/airflow/dags/test.py", line 67, in load
    conn = pg_hook.get_conn()
  File "/Users/jessicamarzin/Desktop/data_science/test_etl/venv/lib/python3.9/site-packages/airflow/providers/postgres/hooks/postgres.py", line 176, in get_conn
    self.conn = psycopg2.connect(**conn_args)
  File "/Users/jessicamarzin/Desktop/data_science/test_etl/venv/lib/python3.9/site-packages/psycopg2/__init__.py", line 122, in connect
    conn = _connect(dsn, connection_factory=connection_factory, **kwasync)
psycopg2.OperationalError: connection to server at "localhost" (::1), port 5432 failed: FATAL:  database "airflow" does not exist

[2024-08-26T14:28:54.763-0500] {local_task_job_runner.py:261} INFO - Task exited with return code 1
[2024-08-26T14:28:54.780-0500] {taskinstance.py:3891} INFO - 0 downstream tasks scheduled from follow-on schedule check
[2024-08-26T14:28:54.781-0500] {local_task_job_runner.py:240} INFO - ::endgroup::
