[2024-08-27T01:17:01.096+0000] {taskinstance.py:1103} INFO - Dependencies all met for dep_context=non-requeueable deps ti=<TaskInstance: mysql_to_postgresql_etl.load scheduled__2024-08-26T01:16:49.954923+00:00 [queued]>
[2024-08-27T01:17:01.108+0000] {taskinstance.py:1103} INFO - Dependencies all met for dep_context=requeueable deps ti=<TaskInstance: mysql_to_postgresql_etl.load scheduled__2024-08-26T01:16:49.954923+00:00 [queued]>
[2024-08-27T01:17:01.109+0000] {taskinstance.py:1308} INFO - Starting attempt 1 of 2
[2024-08-27T01:17:01.128+0000] {taskinstance.py:1327} INFO - Executing <Task(PythonOperator): load> on 2024-08-26 01:16:49.954923+00:00
[2024-08-27T01:17:01.137+0000] {standard_task_runner.py:57} INFO - Started process 762 to run task
[2024-08-27T01:17:01.141+0000] {standard_task_runner.py:84} INFO - Running: ['***', 'tasks', 'run', 'mysql_to_postgresql_etl', 'load', 'scheduled__2024-08-26T01:16:49.954923+00:00', '--job-id', '5', '--raw', '--subdir', 'DAGS_FOLDER/test.py', '--cfg-path', '/tmp/tmpaqcgwpot']
[2024-08-27T01:17:01.144+0000] {standard_task_runner.py:85} INFO - Job 5: Subtask load
[2024-08-27T01:17:01.196+0000] {task_command.py:410} INFO - Running <TaskInstance: mysql_to_postgresql_etl.load scheduled__2024-08-26T01:16:49.954923+00:00 [running]> on host 41675a30b3a8
[2024-08-27T01:17:01.287+0000] {taskinstance.py:1547} INFO - Exporting env vars: AIRFLOW_CTX_DAG_OWNER='***' AIRFLOW_CTX_DAG_ID='mysql_to_postgresql_etl' AIRFLOW_CTX_TASK_ID='load' AIRFLOW_CTX_EXECUTION_DATE='2024-08-26T01:16:49.954923+00:00' AIRFLOW_CTX_TRY_NUMBER='1' AIRFLOW_CTX_DAG_RUN_ID='scheduled__2024-08-26T01:16:49.954923+00:00'
[2024-08-27T01:17:01.335+0000] {base.py:73} INFO - Using connection ID 'postgres_default' for task execution.
[2024-08-27T01:17:01.419+0000] {base.py:73} INFO - Using connection ID 'postgres_default' for task execution.
[2024-08-27T01:17:01.451+0000] {logging_mixin.py:150} INFO - Error in load task: relation "transformed_data6" does not exist
LINE 1: INSERT INTO transformed_data6 (age, bmi, age_group, bmi_grou...
                    ^
[2024-08-27T01:17:01.458+0000] {base.py:73} INFO - Using connection ID 'postgres_default' for task execution.
[2024-08-27T01:17:01.459+0000] {logging_mixin.py:150} INFO - PostgreSQL Connection Info: postgres://postgres:za12zaZA12%21%40@host.docker.internal:5432/postgres
[2024-08-27T01:17:01.459+0000] {taskinstance.py:1824} ERROR - Task failed with exception
Traceback (most recent call last):
  File "/home/airflow/.local/lib/python3.7/site-packages/airflow/operators/python.py", line 181, in execute
    return_value = self.execute_callable()
  File "/home/airflow/.local/lib/python3.7/site-packages/airflow/operators/python.py", line 198, in execute_callable
    return self.python_callable(*self.op_args, **self.op_kwargs)
  File "/opt/airflow/dags/test.py", line 535, in load
    target_fields=['age', 'bmi', 'age_group', 'bmi_group']
  File "/home/airflow/.local/lib/python3.7/site-packages/airflow/providers/common/sql/hooks/sql.py", line 467, in insert_rows
    cur.execute(sql, values)
psycopg2.errors.UndefinedTable: relation "transformed_data6" does not exist
LINE 1: INSERT INTO transformed_data6 (age, bmi, age_group, bmi_grou...
                    ^

[2024-08-27T01:17:01.470+0000] {taskinstance.py:1350} INFO - Marking task as UP_FOR_RETRY. dag_id=mysql_to_postgresql_etl, task_id=load, execution_date=20240826T011649, start_date=20240827T011701, end_date=20240827T011701
[2024-08-27T01:17:01.482+0000] {standard_task_runner.py:109} ERROR - Failed to execute job 5 for task load (relation "transformed_data6" does not exist
LINE 1: INSERT INTO transformed_data6 (age, bmi, age_group, bmi_grou...
                    ^
; 762)
[2024-08-27T01:17:01.528+0000] {local_task_job_runner.py:225} INFO - Task exited with return code 1
[2024-08-27T01:17:01.547+0000] {taskinstance.py:2653} INFO - 0 downstream tasks scheduled from follow-on schedule check
