[2024-08-27T00:46:39.983+0000] {taskinstance.py:1103} INFO - Dependencies all met for dep_context=non-requeueable deps ti=<TaskInstance: mysql_to_postgresql_etl.extract scheduled__2024-08-26T00:46:28.625399+00:00 [queued]>
[2024-08-27T00:46:39.994+0000] {taskinstance.py:1103} INFO - Dependencies all met for dep_context=requeueable deps ti=<TaskInstance: mysql_to_postgresql_etl.extract scheduled__2024-08-26T00:46:28.625399+00:00 [queued]>
[2024-08-27T00:46:39.994+0000] {taskinstance.py:1308} INFO - Starting attempt 1 of 2
[2024-08-27T00:46:40.012+0000] {taskinstance.py:1327} INFO - Executing <Task(PythonOperator): extract> on 2024-08-26 00:46:28.625399+00:00
[2024-08-27T00:46:40.020+0000] {standard_task_runner.py:57} INFO - Started process 597 to run task
[2024-08-27T00:46:40.023+0000] {standard_task_runner.py:84} INFO - Running: ['***', 'tasks', 'run', 'mysql_to_postgresql_etl', 'extract', 'scheduled__2024-08-26T00:46:28.625399+00:00', '--job-id', '4', '--raw', '--subdir', 'DAGS_FOLDER/test.py', '--cfg-path', '/tmp/tmp1xxgocyl']
[2024-08-27T00:46:40.026+0000] {standard_task_runner.py:85} INFO - Job 4: Subtask extract
[2024-08-27T00:46:40.080+0000] {task_command.py:410} INFO - Running <TaskInstance: mysql_to_postgresql_etl.extract scheduled__2024-08-26T00:46:28.625399+00:00 [running]> on host f00156c30bb5
[2024-08-27T00:46:40.174+0000] {taskinstance.py:1547} INFO - Exporting env vars: AIRFLOW_CTX_DAG_OWNER='***' AIRFLOW_CTX_DAG_ID='mysql_to_postgresql_etl' AIRFLOW_CTX_TASK_ID='extract' AIRFLOW_CTX_EXECUTION_DATE='2024-08-26T00:46:28.625399+00:00' AIRFLOW_CTX_TRY_NUMBER='1' AIRFLOW_CTX_DAG_RUN_ID='scheduled__2024-08-26T00:46:28.625399+00:00'
[2024-08-27T00:46:40.185+0000] {base.py:73} INFO - Using connection ID 'mysql_default' for task execution.
[2024-08-27T00:46:40.200+0000] {logging_mixin.py:150} INFO - Error in extract task: (2003, "Can't connect to MySQL server on '127.0.0.1:3306' (111)")
[2024-08-27T00:46:40.201+0000] {taskinstance.py:1824} ERROR - Task failed with exception
Traceback (most recent call last):
  File "/home/airflow/.local/lib/python3.7/site-packages/airflow/operators/python.py", line 181, in execute
    return_value = self.execute_callable()
  File "/home/airflow/.local/lib/python3.7/site-packages/airflow/operators/python.py", line 198, in execute_callable
    return self.python_callable(*self.op_args, **self.op_kwargs)
  File "/opt/airflow/dags/test.py", line 317, in extract
    df = mysql_hook.get_pandas_df(sql=query)
  File "/home/airflow/.local/lib/python3.7/site-packages/airflow/providers/common/sql/hooks/sql.py", line 200, in get_pandas_df
    with closing(self.get_conn()) as conn:
  File "/home/airflow/.local/lib/python3.7/site-packages/airflow/providers/mysql/hooks/mysql.py", line 188, in get_conn
    return MySQLdb.connect(**conn_config)
  File "/home/airflow/.local/lib/python3.7/site-packages/MySQLdb/__init__.py", line 123, in Connect
    return Connection(*args, **kwargs)
  File "/home/airflow/.local/lib/python3.7/site-packages/MySQLdb/connections.py", line 185, in __init__
    super().__init__(*args, **kwargs2)
MySQLdb.OperationalError: (2003, "Can't connect to MySQL server on '127.0.0.1:3306' (111)")
[2024-08-27T00:46:40.210+0000] {taskinstance.py:1350} INFO - Marking task as UP_FOR_RETRY. dag_id=mysql_to_postgresql_etl, task_id=extract, execution_date=20240826T004628, start_date=20240827T004639, end_date=20240827T004640
[2024-08-27T00:46:40.224+0000] {standard_task_runner.py:109} ERROR - Failed to execute job 4 for task extract ((2003, "Can't connect to MySQL server on '127.0.0.1:3306' (111)"); 597)
[2024-08-27T00:46:40.242+0000] {local_task_job_runner.py:225} INFO - Task exited with return code 1
[2024-08-27T00:46:40.272+0000] {taskinstance.py:2653} INFO - 0 downstream tasks scheduled from follow-on schedule check
